Workbook

Sheet Plant Costs | CAPEX and OPEX
A1: Fixed OPEX breakdown | E1: Assumptions | H1: CAPEX breakdown
A3: Labour | B3: Shift Positions | E3: Factoring multiplier for ISBL | F3: 3.3 | H3: ISBL cost | I3: 3.3*Bare equipment cost
B4: Supervisions | C4: 25% of Shift positions | E4: Life time factor [y] | F4: 20 | H4: OSBL cost | I4: 40%*ISBL
B5: Direct Overhead | C5: 45% of Shift positions and Supervisions | E5: interest rate [%] | F5: 15 | H5: Engineering costs (EN) | I5: 10%* (ISBL+OSBL)
A6: Maintenance | C6: 3% of Total Fixed Capital Cost | E6: Annual Capital Charge Ratio (ACCR) | F6: =F5/100*(1+F5/100)^F4/((1+F5/100)^F4-1) -> 0.15976147 | H6: Contingency (CN) | I6: 10%* (ISBL+OSBL)
A7: Overhead Expense | B7: Plant Overhead | C7: 65% Labour and Maintenance | E7: Operators per shift position | F7: 4.8 | H7: Working capital | I7: 5%*(ISBL+OSBL+ EN+ CN)
B8: Tax and Insurance | C8: 1.5% of Total Fixed Capital Cost | E8: Number of shift positions | F8: 10
E9: Average salary per shift [€/y]* | F9: 63037
A10: CAPEX and OPEX breakdowns are assummed based on: https://doi.org/10.1016/j.jclepro.2025.145114 | F10: *https://www.erieri.com/salary/job/refinery-operator/netherlands
A11: Data for capacities and equipment costs are given from: https://link.springer.com/article/10.1007/s43615-024-00410-5
A14: Reference component → | B14: EB | C14: MTBE | D14: C2E | E14: PO | F14: PGME | G14: PO | H14: C2E | I14: BZ | J14: NAPHTHA | K14: i-C4E | L14: MEOH | M14: C2E
A15: Plant → | B15: Ethylbenzene | C15: MTBE production | D15: Olefins | E15: Propylene oxide | F15: Propylene glycol | G15: Propylene oxide/Styrene monomer | H15: Methanol to olefins | I15: Methanol to aromatics | J15: Plastic waste pyrolysis | K15: Biomass to isobutylene via organosolv | L15: CO2 hydrogeneration | M15: Electrochemical reduction of CO2 to ethylene
A16: Capacity based on main product [kt/y]→ | B16: 783.9 | C16: 400 | D16: 878.2 | E16: 253.6 | F16: 89.6 | G16: 295.6 | H16: 314.4 | I16: 532.3 | J16: 1050 | K16: 358.4 | L16: 403.3 | M16: 328.2
A17: Equipment Cost → | B17: 5646080 | C17: =3214700+5279380 -> 8494080 | D17: 177271120 | E17: 33156880 | F17: 3455810 | G17: 48799760 | H17: 55321100 | I17: 480367100 | J17: 135395500 | K17: 314379508 | L17: 74116400 | M17: 111131800
A19: CAPEX breakdown ↓
A20: ISBL | B20: =$F$3*B17/10^6 -> 18.632064 | C20: =$F$3*C17/10^6 -> 28.030464 | D20: =$F$3*D17/10^6 -> 584.9947 | E20: 109.4177 | F20: =$F$3*F17/10^6 -> 11.404173 | G20: =$F$3*G17/10^6 -> 161.03921 | H20: =$F$3*H17/10^6 -> 182.55963 | I20: =$F$3*I17/10^6 -> 1585.2114 | J20: =$F$3*J17/10^6 -> 446.80515 | K20: =$F$3*K17/10^6 -> 1037.4524 | L20: =$F$3*L17/10^6 -> 244.58412 | M20: =$F$3*M17/10^6 -> 366.73494
A21: OSBL | B21: =0.4*B20 -> 7.4528256 | C21: =0.4*C20 -> 11.212186 | D21: =0.4*D20 -> 233.99788 | E21: 43.767082 | F21: =0.4*F20 -> 4.5616692 | G21: =0.4*G20 -> 64.415683 | H21: =0.4*H20 -> 73.023852 | I21: =0.4*I20 -> 634.08457 | J21: =0.4*J20 -> 178.72206 | K21: =0.4*K20 -> 414.98095 | L21: =0.4*L20 -> 97.833648 | M21: =0.4*M20 -> 146.69398
A22: Engineering Cost | B22: =0.1*(B20+B21) -> 2.608489 | C22: =0.1*(C20+C21) -> 3.924265 | D22: =0.1*(D20+D21) -> 81.899257 | E22: 15.318479 | F22: =0.1*(F20+F21) -> 1.5965842 | G22: =0.1*(G20+G21) -> 22.545489 | H22: =0.1*(H20+H21) -> 25.558348 | I22: =0.1*(I20+I21) -> 221.9296 | J22: =0.1*(J20+J21) -> 62.552721 | K22: =0.1*(K20+K21) -> 145.24333 | L22: =0.1*(L20+L21) -> 34.241777 | M22: =0.1*(M20+M21) -> 51.342892
A23: Contingency | B23: =0.1*(B20+B21) -> 2.608489 | C23: =0.1*(C20+C21) -> 3.924265 | D23: =0.1*(D20+D21) -> 81.899257 | E23: 15.318479 | F23: =0.1*(F20+F21) -> 1.5965842 | G23: =0.1*(G20+G21) -> 22.545489 | H23: =0.1*(H20+H21) -> 25.558348 | I23: =0.1*(I20+I21) -> 221.9296 | J23: =0.1*(J20+J21) -> 62.552721 | K23: =0.1*(K20+K21) -> 145.24333 | L23: =0.1*(L20+L21) -> 34.241777 | M23: =0.1*(M20+M21) -> 51.342892
A24: Working Capital | B24: =0.05*(B20+B21+B22+B23) -> 1.5650934 | C24: =0.05*(C20+C21+C22+C23) -> 2.354559 | D24: =0.05*(D20+D21+D22+D23) -> 49.139554 | E24: 9.1910871 | F24: =0.05*(F20+F21+F22+F23) -> 0.95795053 | G24: =0.05*(G20+G21+G22+G23) -> 13.527293 | H24: =0.05*(H20+H21+H22+H23) -> 15.335009 | I24: =0.05*(I20+I21+I22+I23) -> 133.15776 | J24: =0.05*(J20+J21+J22+J23) -> 37.531633 | K24: =0.05*(K20+K21+K22+K23) -> 87.146 | L24: =0.05*(L20+L21+L22+L23) -> 20.545066 | M24: =0.05*(M20+M21+M22+M23) -> 30.805735
A25: capex → | B25: =(B20+B21+B22+B23+B24) -> 32.866961 | C25: =(C20+C21+C22+C23+C24) -> 49.445738 | D25: =(D20+D21+D22+D23+D24) -> 1031.9306 | E25: 193.01283 | F25: =(F20+F21+F22+F23+F24) -> 20.116961 | G25: =(G20+G21+G22+G23+G24) -> 284.07316 | H25: =(H20+H21+H22+H23+H24) -> 322.03519 | I25: =(I20+I21+I22+I23+I24) -> 2796.313 | J25: =(J20+J21+J22+J23+J24) -> 788.16428 | K25: 2004 | L25: =(L20+L21+L22+L23+L24) -> 431.44639 | M25: =(M20+M21+M22+M23+M24) -> 646.92043
A26: Annual Depreciation (straight-line) → | B26: =B25/$F$4 -> 1.643348 | C26: =C25/$F$4 -> 2.4722869 | D26: =D25/$F$4 -> 51.596532 | E26: 9.6506415 | F26: =F25/$F$4 -> 1.0058481 | G26: =G25/$F$4 -> 14.203658 | H26: =H25/$F$4 -> 16.101759 | I26: =I25/$F$4 -> 139.81565 | J26: =J25/$F$4 -> 39.408214 | K26: =K25/$F$4 -> 100.2 | L26: =L25/$F$4 -> 21.572319 | M26: =M25/$F$4 -> 32.346022
A28: Fixed OPEX breakdown
A29: Shift positions | B29: =$F$7*$F$8*$F$9/10^6 -> 3.025776 | C29: =$F$7*$F$8*$F$9/10^6 -> 3.025776 | D29: =$F$7*$F$8*$F$9/10^6 -> 3.025776 | E29: 3.025776 | F29: =$F$7*$F$8*$F$9/10^6 -> 3.025776 | G29: =$F$7*$F$8*$F$9/10^6 -> 3.025776 | H29: =$F$7*$F$8*$F$9/10^6 -> 3.025776 | I29: =$F$7*$F$8*$F$9/10^6 -> 3.025776 | J29: =$F$7*$F$8*$F$9/10^6 -> 3.025776 | K29: =$F$7*$F$8*$F$9/10^6 -> 3.025776 | L29: =$F$7*$F$8*$F$9/10^6 -> 3.025776 | M29: =$F$7*$F$8*$F$9/10^6 -> 3.025776
A30: Supervisions | B30: =0.25*B29 -> 0.756444 | C30: =0.25*C29 -> 0.756444 | D30: =0.25*D29 -> 0.756444 | E30: 0.756444 | F30: =0.25*F29 -> 0.756444 | G30: =0.25*G29 -> 0.756444 | H30: =0.25*H29 -> 0.756444 | I30: =0.25*I29 -> 0.756444 | J30: =0.25*J29 -> 0.756444 | K30: =0.25*K29 -> 0.756444 | L30: =0.25*L29 -> 0.756444 | M30: =0.25*M29 -> 0.756444
A31: Direct overhead | B31: =0.45*(B29+B30) -> 1.701999 | C31: =0.45*(C29+C30) -> 1.701999 | D31: =0.45*(D29+D30) -> 1.701999 | E31: 1.701999 | F31: =0.45*(F29+F30) -> 1.701999 | G31: =0.45*(G29+G30) -> 1.701999 | H31: =0.45*(H29+H30) -> 1.701999 | I31: =0.45*(I29+I30) -> 1.701999 | J31: =0.45*(J29+J30) -> 1.701999 | K31: =0.45*(K29+K30) -> 1.701999 | L31: =0.45*(L29+L30) -> 1.701999 | M31: =0.45*(M29+M30) -> 1.701999
A32: Maintenance | B32: =0.03*B25 -> 0.98600883 | C32: =0.03*C25 -> 1.4833722 | D32: =0.03*D25 -> 30.957919 | E32: 5.7903849 | F32: =0.03*F25 -> 0.60350884 | G32: =0.03*G25 -> 8.5221949 | H32: =0.03*H25 -> 9.6610556 | I32: =0.03*I25 -> 83.889389 | J32: =0.03*J25 -> 23.644929 | K32: =0.03*K25 -> 60.12 | L32: =0.03*L25 -> 12.943392 | M32: =0.03*M25 -> 19.407613
A33: Plant overhead | B33: =0.65*(B29+B30+B31+B32) -> 4.2056481 | C33: =0.65*(C29+C30+C31+C32) -> 4.5289343 | D33: =0.65*(D29+D30+D31+D32) -> 23.68739 | E33: 7.3284925 | F33: =0.65*(F29+F30+F31+F32) -> 3.9570231 | G33: =0.65*(G29+G30+G31+G32) -> 9.104169 | H33: =0.65*(H29+H30+H31+H32) -> 9.8444285 | I33: =0.65*(I29+I30+I31+I32) -> 58.092845 | J33: =0.65*(J29+J30+J31+J32) -> 18.933946 | K33: =0.65*(K29+K30+K31+K32) -> 42.642742 | L33: =0.65*(L29+L30+L31+L32) -> 11.977947 | M33: =0.65*(M29+M30+M31+M32) -> 16.179691
A34: Tax and insurance | B34: =0.015*B25 -> 0.49300441 | C34: =0.015*C25 -> 0.74168608 | D34: =0.015*D25 -> 15.47896 | E34: 2.8951924 | F34: =0.015*F25 -> 0.30175442 | G34: =0.015*G25 -> 4.2610974 | H34: =0.015*H25 -> 4.8305278 | I34: =0.015*I25 -> 41.944694 | J34: =0.015*J25 -> 11.822464 | K34: =0.015*K25 -> 30.06 | L34: =0.015*L25 -> 6.4716958 | M34: =0.015*M25 -> 9.7038065
A35: Fixed opex → | B35: =SUM(B29:B34) -> 11.16888 | C35: =SUM(C29:C34) -> 12.238211 | D35: =SUM(D29:D34) -> 75.608488 | E35: 21.498289 | F35: =SUM(F29:F34) -> 10.346505 | G35: =SUM(G29:G34) -> 27.37168 | H35: =SUM(H29:H34) -> 29.820231 | I35: =SUM(I29:I34) -> 189.41115 | J35: =SUM(J29:J34) -> 59.885558 | K35: =SUM(K29:K34) -> 138.30696 | L35: =SUM(L29:L34) -> 36.877253 | M35: =SUM(M29:M34) -> 50.775329
A36: Fixed opex [€/t] → | B36: =#REF!*10^6/#REF!/10^3 -> #REF! | C36: =B35*10^6/B16/10^3 -> 14.247838 | D36: =C35*10^6/C16/10^3 -> 30.595529 | E36: =#REF!*10^6/#REF!/10^3 -> #REF! | F36: =E35*10^6/E16/10^3 -> 84.772432 | G36: =D35*10^6/D16/10^3 -> 86.094839 | H36: =#REF!*10^6/#REF!/10^3 -> #REF! | I36: =#REF!*10^6/#REF!/10^3 -> #REF! | J36: =F35*10^6/F16/10^3 -> 115.47439 | K36: =G35*10^6/G16/10^3 -> 92.597024 | L36: =H35*10^6/H16/10^3 -> 94.848063 | M36: =I35*10^6/I16/10^3 -> 355.83533 | N36: =J35*10^6/J16/10^3 -> 57.033864 | O36: =K35*10^6/K16/10^3 -> 385.90112 | P36: =L35*10^6/L16/10^3 -> 91.438764 | Q36: =M35*10^6/M16/10^3 -> 154.7085 | R36: =R35*10^6/R16/10^3 -> #DIV/0! | S36: =S35*10^6/S16/10^3 -> #DIV/0! | T36: =T35*10^6/T16/10^3 -> #DIV/0! | U36: =U35*10^6/U16/10^3 -> #DIV/0! | V36: =V35*10^6/V16/10^3 -> #DIV/0! | W36: =W35*10^6/W16/10^3 -> #DIV/0! | X36: =X35*10^6/X16/10^3 -> #DIV/0! | Y36: =Y35*10^6/Y16/10^3 -> #DIV/0!

Sheet Steam Prices Calculations
A1: Reference for natural gas price: https://www.statista.com/statistics/673333/monthly-prices-for-natural-gas-in-the-united-states-and-europe/
A2: Calculations done based on https://www.energy.1051gov/sites/prod/files/2014/05/f15/tech\_brief\_true\_cost.pdf.
B4: Steams specifications ↓
B5: Steams | C5: Temp | D5: P | E5: kJ/kg | F5: Btu/lb | G5: kJ/kg | H5: Btu/lb
B6: LLPS | C6: 143.8 | D6: 3.9 | E6: 604.9 | F6: =E6*2.326 -> 1406.9974 | G6: 2738.5 | H6: =G6*2.326 -> 6369.751
B7: LPS | C7: 155 | D7: 5.5 | E7: 655.55 | F7: =E7*2.326 -> 1524.8093 | G7: 2752.65 | H7: =G7*2.326 -> 6402.6639
B8: MPS | C8: 214 | D8: 21 | E8: 922.53 | F8: =E8*2.326 -> 2145.8048 | G8: 2799.75 | H8: =G8*2.326 -> 6512.2185
B9: HPS | C9: 265 | D9: 51 | E9: 1154.22 | F9: =E9*2.326 -> 2684.7157 | G9: 2793.7 | H9: =G9*2.326 -> 6498.1462
B13: Natural Gas (Statista) | C13: Unit conversion | D13: HPS | E13: MPS | F13: LPS | G13: LLPS
A14: Date | B14: Price(per MMBtu) | C14: Price(per GJ) | D14: Price(per GJ) | E14: Price(per GJ) | F14: Price(per GJ) | G14: Price(per GJ)
A15: 43101 | B15: 7.56 | C15: =B15*3.421/3.6 -> 7.1841 | D15: =C15*(1+0.3)/0.85 -> 10.987447 | E15: =D15*($G$9-$E$9)/($G$8-$E$8) -> 9.5959449 | F15: =E15*($G$8-$E$8)/($G$7-$E$7) -> 8.5898144 | G15: =F15*($G$7-$E$7)/($G$6-$E$6) -> 8.4428664
A16: 43132 | B16: 6.87 | C16: =B16*3.421/3.6 -> 6.5284083 | D16: =C16*(1+0.3)/0.85 -> 9.9846245 | E16: =D16*($G$9-$E$9)/($G$8-$E$8) -> 8.7201245 | F16: =E16*($G$8-$E$8)/($G$7-$E$7) -> 7.8058234 | G16: =F16*($G$7-$E$7)/($G$6-$E$6) -> 7.6722873
A17: 43160 | B17: 7.03 | C17: =B17*3.421/3.6 -> 6.6804528 | D17: =C17*(1+0.3)/0.85 -> 10.217163 | E17: =D17*($G$9-$E$9)/($G$8-$E$8) -> 8.9232133 | F17: =E17*($G$8-$E$8)/($G$7-$E$7) -> 7.9876184 | G17: =F17*($G$7-$E$7)/($G$6-$E$6) -> 7.8509723
A18: 43191 | B18: 7.81 | C18: =B18*3.421/3.6 -> 7.4216694 | D18: =C18*(1+0.3)/0.85 -> 11.350789 | E18: =D18*($G$9-$E$9)/($G$8-$E$8) -> 9.9132711 | F18: =E18*($G$8-$E$8)/($G$7-$E$7) -> 8.8738691 | G18: =F18*($G$7-$E$7)/($G$6-$E$6) -> 8.7220617
A19: 43221 | B19: 7.19 | C19: =B19*3.421/3.6 -> 6.8324972 | D19: =C19*(1+0.3)/0.85 -> 10.449702 | E19: =D19*($G$9-$E$9)/($G$8-$E$8) -> 9.1263021 | F19: =E19*($G$8-$E$8)/($G$7-$E$7) -> 8.1694134 | G19: =F19*($G$7-$E$7)/($G$6-$E$6) -> 8.0296573
A20: 43252 | B20: 7.19 | C20: =B20*3.421/3.6 -> 6.8324972 | D20: =C20*(1+0.3)/0.85 -> 10.449702 | E20: =D20*($G$9-$E$9)/($G$8-$E$8) -> 9.1263021 | F20: =E20*($G$8-$E$8)/($G$7-$E$7) -> 8.1694134 | G20: =F20*($G$7-$E$7)/($G$6-$E$6) -> 8.0296573
A21: 43282 | B21: 7.25 | C21: =B21*3.421/3.6 -> 6.8895139 | D21: =C21*(1+0.3)/0.85 -> 10.536904 | E21: =D21*($G$9-$E$9)/($G$8-$E$8) -> 9.2024604 | F21: =E21*($G$8-$E$8)/($G$7-$E$7) -> 8.2375865 | G21: =F21*($G$7-$E$7)/($G$6-$E$6) -> 8.0966642
A22: 43313 | B22: 7.98 | C22: =B22*3.421/3.6 -> 7.5832167 | D22: =C22*(1+0.3)/0.85 -> 11.597861 | E22: =D22*($G$9-$E$9)/($G$8-$E$8) -> 10.129053 | F22: =E22*($G$8-$E$8)/($G$7-$E$7) -> 9.0670263 | G22: =F22*($G$7-$E$7)/($G$6-$E$6) -> 8.9119145
A23: 43344 | B23: 8.2 | C23: =B23*3.421/3.6 -> 7.7922778 | D23: =C23*(1+0.3)/0.85 -> 11.917601 | E23: =D23*($G$9-$E$9)/($G$8-$E$8) -> 10.4083 | F23: =E23*($G$8-$E$8)/($G$7-$E$7) -> 9.3169944 | G23: =F23*($G$7-$E$7)/($G$6-$E$6) -> 9.1576064
A24: 43374 | B24: 8.79 | C24: =B24*3.421/3.6 -> 8.3529417 | D24: =C24*(1+0.3)/0.85 -> 12.775087 | E24: =D24*($G$9-$E$9)/($G$8-$E$8) -> 11.15719 | F24: =E24*($G$8-$E$8)/($G$7-$E$7) -> 9.9873635 | G24: =F24*($G$7-$E$7)/($G$6-$E$6) -> 9.8165073
A25: 43405 | B25: 8.27 | C25: =B25*3.421/3.6 -> 7.8587972 | D25: =C25*(1+0.3)/0.85 -> 12.019337 | E25: =D25*($G$9-$E$9)/($G$8-$E$8) -> 10.497151 | F25: =E25*($G$8-$E$8)/($G$7-$E$7) -> 9.3965297 | G25: =F25*($G$7-$E$7)/($G$6-$E$6) -> 9.2357811
A26: 43435 | B26: 7.98 | C26: =B26*3.421/3.6 -> 7.5832167 | D26: =C26*(1+0.3)/0.85 -> 11.597861 | E26: =D26*($G$9-$E$9)/($G$8-$E$8) -> 10.129053 | F26: =E26*($G$8-$E$8)/($G$7-$E$7) -> 9.0670263 | G26: =F26*($G$7-$E$7)/($G$6-$E$6) -> 8.9119145
... A98: 45627 | B98: 13.86 | C98: =B98*3.421/3.6 -> 13.17085 | D98: =C98*(1+0.3)/0.85 -> 20.143653 | E98: =D98*($G$9-$E$9)/($G$8-$E$8) -> 17.592566 | F98: =E98*($G$8-$E$8)/($G$7-$E$7) -> 15.747993 | G98: =F98*($G$7-$E$7)/($G$6-$E$6) -> 15.478588

Sheet Historical Prices References
A4: Reference → | B4: Reference Source
A5: Resources ↓
A6: Ethylene oxide (EO) | B6: https://businessanalytiq.com/procurementanalytics/index/ethylene-oxide-price-index/
A7: Ethylene (C2E) | B7: https://businessanalytiq.com/procurementanalytics/index/ethylene-price-index/
A8: Ethylbenzene (EB) | B8: According to the historical prices of ethylene and benzene and their mixure porpotions for ethylbenzne
A9: Benzene (BZ) | B9: https://businessanalytiq.com/procurementanalytics/index/benzene-price-index/
A10: Ethylene glycol (MEG) | B10: https://businessanalytiq.com/procurementanalytics/index/ethylene-glycol-price-index/
A11: Methanol (MeOH) | B11: https://businessanalytiq.com/procurementanalytics/index/methanol-price-index/
A12: Methyl tert-butyl ether (MTBE) | B12: https://businessanalytiq.com/procurementanalytics/index/mtbe-price-index/
A13: Tert butyl alcohol (t-BuOH/TBA) | B13: https://businessanalytiq.com/procurementanalytics/index/butanol-price-index/
A14: Isobutane (i-C4A) | B14: https://businessanalytiq.com/procurementanalytics/index/isobutanol-price-index/
A15: Naphtha (Naphtha) | B15: https://businessanalytiq.com/procurementanalytics/index/naphtha-price-index/
A16: Propylene (C3E) | B16: https://businessanalytiq.com/procurementanalytics/index/propylene-price-index/
A17: Butadiene (XXX) | B17: https://businessanalytiq.com/procurementanalytics/index/butadiene-price-index/
... A35: H2 | B35: https://businessanalytiq.com/procurementanalytics/index/grey-hydrogen-price-index/
A37: Remarks:
A38: It is based on histroical pricing data.
A39: For calculation simplicity, all data is assumed in euro.
A40: It should be noted that currency exchange does not have any effects of variance, and other ralative parameters.
A41: In Tan et. al., LDPE is cosidered as a main PE for modeling.
A42: As no specific price variation for PP and PE wastes is available, two ratios are assummed as a basis for calucating their waste prices.
A43: PP waste = 0.75 PP
A44: PE waste = 0.4 PE
A45: https://ec.europa.eu/eurostat/statistics-explained/index.php?title=Recycling_%E2%80%93_secondary_material_price_indicator

Sheet Re-costed Prices Calculations
E1: For the detailed calculation procedures, refer to Appendix B, which outlines the corresponding steps and mathematical formulas used. | DW1: ↓ In this case, negative ratio is considered as one to avoid negative effects.
E2: Remark: Data for year 2021 was not implemented due to covid-related disruptions.
C5: Methanol-to-olefins | W5: Olefins (as a basis) | AN5: Methanol-to-aromatics | BU5: Plastic Waste Pyrolysis | CV5: CO2 Hydrogeneration | DC5: Electrochemical Reduction of CO2 to Ethylene | DJ5: MTBE Production (as a basis) | DW5: Biomass to isobutylene via organosolv
C6: Price allocation | F6: Ratio of price allocation | I6: Divided expenses among Res. | L6: Price for zero price balance | O6: Added value wrt market price | R6: Added value wrt base profit | W6: Price allocation | Z6: Ratio of price allocation | AC6: Divided expenses among Res. | AF6: Price for zero price balance | AI6: Added value wrt market price | AN6: Price allocation | AS6: Ratio of price allocation | AX6: Divided expenses among Res. | BC6: Price for zero price balance | BH6: Added value wrt market price | BM6: Added value wrt base profit | BU6: Price allocation | BY6: Ratio of price allocation | CC6: Divided expenses among Res. | CG6: Price for zero price balance | CK6: Added value wrt market price | CO6: Added value wrt base profit | DJ6: Price allocation | DL6: Ratio of price allocation | DN6: Divided expenses among Res. | DP6: Price for zero price balance | DR6: Added value wrt base profit
C7: 314.4 | D7: 79.74 | E7: 397.69 | W7: 878.2 | X7: 684.9 | Y7: 497.4 | AN7: 532.3 | AO7: 20.3 | AP7: 67.8 | AQ7: 828.9 | AR7: 971.9 | BU7: 4.41 | BV7: 1050 | BW7: 1456.434 | BX7: 1333.185 | CV7: 403.3 | DC7: 328.2 | DJ7: 400 | DK7: 98 | DW7: 358.4
A8: Date ↓ | B8: Sources ↓ | C8: C2E | D8: BZ | E8: CthreeE | F8: C2E | G8: BZ | H8: CthreeE | I8: C2E | J8: BZ | K8: CthreeE | L8: C2E | M8: BZ | N8: CthreeE | O8: C2E | P8: BZ | Q8: CthreeE | R8: C2E | S8: BZ | T8: CthreeE | V8: Sources ↓ | W8: C2E | X8: BZ | Y8: CthreeE | Z8: C2E | AA8: BZ | AB8: CthreeE | AC8: C2E | AD8: BZ | AE8: CthreeE | AF8: C2E | AG8: BZ | AH8: CthreeE | AI8: C2E | AJ8: BZ | AK8: CthreeE | AM8: Sources ↓ | AN8: BZ | AO8: C2E | AP8: C3E | AQ8: n-C4A | AR8: P-xylene | AS8: BZ | AT8: C2E | AU8: C3E | AV8: n-C4A | AW8: P-xylene | AX8: BZ | AY8: C2E | AZ8: C3E | BA8: n-C4A | BB8: P-xylene | BC8: BZ | BD8: C2E | BE8: C3E | BF8: n-C4A | BG8: P-xylene | BH8: BZ | BI8: C2E | BJ8: C3E | BK8: n-C4A | BL8: P-xylene | BM8: BZ | BN8: C2E | BO8: C3E | BP8: n-C4A | BQ8: P-xylene | BT8: Sources ↓ | BU8: BZ | BV8: Naphtha | BW8: Diesel | BX8: VGO | BY8: BZ | BZ8: Naphtha | CA8: Diesel | CB8: VGO | CC8: BZ | CD8: Naphtha | CE8: Diesel | CF8: VGO | CG8: BZ | CH8: Naphtha | CI8: Diesel | CJ8: VGO | CK8: BZ | CL8: Naphtha | CM8: Diesel | CN8: VGO | CO8: BZ | CP8: Naphtha | CQ8: Diesel | CR8: VGO | CU8: Sources ↓ | CV8: MeOH | DB8: Sources ↓ | DC8: C2E | DD8: C2E | DE8: C2E | DF8: C2E | DJ8: MTBE | DK8: i-C4E | DL8: MTBE | DM8: i-C4E | DN8: MTBE | DO8: i-C4E | DP8: MTBE | DQ8: i-C4E | DR8: MTBE | DS8: i-C4E | DV8: Sources ↓ | DW8: i-C4E | DX8: i-C4E | DY8: i-C4E | DZ8: i-C4E
A9: 43101 | DB9: -107.92707 | DC9: 3.9461451 | DD9: 3.1980267 | DE9: 4.1980267 | DI9: -44.980243 | DJ9: 26.333333 | DK9: 23.846667 | DL9: 0.52477747 | DM9: 0.47522253 | DN9: -23.604618 | DO9: -21.375625 | DP9: 0.70813855 | DQ9: 2.6174235 | DR9: 0.1156009 | DS9: 0.1156009
A10: 43132 | DB10: -107.9065 | DC10: 3.9453931 | DD10: 3.0674156 | DE10: 4.0674156 | DI10: -44.905974 | DJ10: 26.333333 | DK10: 25.643333 | DL10: 0.50663759 | DM10: 0.49336241 | DN10: -22.751055 | DO10: -22.154919 | DP10: 0.68253164 | DQ10: 2.7128473 | DR10: 0.15745551 | DS10: 0.15745551
A11: 43160 | B11: -90.68585 | C11: 26.2 | D11: 5.8476 | E11: 34.135058 | F11: 0.3958741 | G11: 0.088355472 | H11: 0.51577043 | I11: -35.900179 | J11: -8.0125911 | K11: -46.77308 | L11: 1.3702358 | M11: 1.2058075 | N11: 1.4113429 | O11: 0.37023583 | P11: 0.37023583 | Q11: 0.37023583 | R11: 1.8322846 | S11: 1.8322846 | T11: 1.8322846 | V11: -124.21654 | W11: 73.183333 | X11: 50.226 | Y11: 42.6935 | Z11: 0.44059052 | AA11: 0.30237895 | AB11: 0.25703053 | AC11: -54.72863 | AD11: -37.560467 | AE11: -31.927444 | AF11: 0.74782915 | AG11: 0.65808966 | AH11: 0.77026403 | AI11: -0.33720382 | AJ11: -0.33720382 | AK11: -0.33720382 | AM11: -342.53047 | AN11: 39.035333 | AO11: 1.6916667 | AP11: 5.8195 | AQ11: 73.2195 | AR11: 73.702417 | AS11: 0.20176592 | AT11: 0.0087438906 | AU11: 0.030079845 | AV11: 0.37845712 | AW11: 0.38095322 | AX11: -69.110976 | AY11: -2.9950489 | AZ11: -10.303263 | BA11: -129.6331 | BB11: -130.48809 | BC11: 1.5580156 | BD11: 1.7704723 | BE11: 1.8235865 | BF11: 1.8767006 | BG11: 1.6111298 | BH11: 0.77047228 | BI11: 0.77047228 | BJ11: 0.77047228 | BK11: 0.77047228 | BL11: 0.77047228 | BM11: 2.3674823 | BN11: 2.3674823 | BO11: 2.3674823 | BP11: 2.3674823 | BQ11: 2.3674823 | DB11: -107.91127 | DC11: 3.9455675 | DD11: 2.9455675 | DE11: 3.9455675 | DI11: -46.992381 | DJ11: 27.333333 | DK11: 24.255 | DL11: 0.52983556 | DM11: 0.47016444 | DN11: -24.898234 | DO11: -22.094146 | DP11: 0.74694702 | DQ11: 2.7054057 | DR11: 0.097802084 | DS11: 0.097802084
A12: 43191 | B12: -86.472334 | C12: 26.724 | D12: 5.9805 | E12: 35.7921 | F12: 0.39015075 | G12: 0.087310903 | H12: 0.52253834 | I12: -33.737246 | J12: -7.5499775 | K12: -45.18511 | L12: 1.2876811 | M12: 1.1361892 | N12: 1.3634271 | O12: 0.26243249 | P12: 0.26243249 | Q12: 0.26243249 | R12: 1.6017616 | S12: 1.6017616 | T12: 1.6017616 | V12: -134.60109 | W12: 74.647 | X12: 51.3675 | Y12: 44.766 | Z12: 0.43709323 | AA12: 0.30078083 | AB12: 0.26212595 | AC12: -58.833225 | AD12: -40.485427 | AE12: -35.282438 | AF12: 0.80391562 | AG12: 0.70933731 | AH12: 0.85120477 | AI12: -0.26878988 | AJ12: -0.26878988 | AK12: -0.26878988 | AM12: -324.51003 | AN12: 39.9225 | AO12: 1.7255 | AP12: 6.102 | AQ12: 78.7455 | AR12: 77.752 | AS12: 0.19546139 | AT12: 0.0084480838 | AU12: 0.029875519 | AV12: 0.3855396 | AW12: 0.38067541 | AX12: -63.429181 | AY12: -2.7414879 | AZ12: -9.6949054 | BA12: -125.11147 | BB12: -123.53299 | BC12: 1.4299271 | BD12: 1.620584 | BE12: 1.7159125 | BF12: 1.8112409 | BG12: 1.5252555 | BH12: 0.58880784 | BI12: 0.58880784 | BJ12: 0.58880784 | BK12: 0.58880784 | BL12: 0.58880784 | BM12: 2.0158633 | BN12: 2.0158633 | BO12: 2.0158633 | BP12: 2.0158633 | BQ12: 2.0158633 | DB12: -107.93452 | DC12: 3.9464175 | DD12: 2.8690368 | DE12: 3.8690368 | DF12: 4.9089947 | DI12: -46.736485 | DJ12: 27.666667 | DK12: 24.581667 | DL12: 0.52952247 | DM12: 0.47047753 | DN12: -24.748019 | DO12: -21.988466 | DP12: 0.74244058 | DQ12: 2.6924652 | DR12: 0.11793459 | DS12: 0.11793459
A13: 43221 | B13: -95.028524 | C13: 27.248 | D13: 6.1134 | E13: 36.123508 | F13: 0.39214271 | G13: 0.087981695 | H13: 0.5198756 | I13: -37.264743 | J13: -8.3607706 | K13: -49.403011 | L13: 1.4223184 | M13: 1.2582048 | N13: 1.4906991 | O13: 0.36761386 | P13: 0.36761386 | Q13: 0.36761386 | R13: 1.6472573 | S13: 1.6472573 | T13: 1.6472573 | V13: -144.29532 | W13: 76.110667 | X13: 52.509 | Y13: 45.1805 | Z13: 0.43792056 | AA13: 0.30212284 | AB13: 0.2599566 | AC13: -63.189888 | AD13: -43.594912 | AE13: -37.510521 | AF13: 0.86344643 | AG13: 0.763818 | AH13: 0.90495828 | AI13: -0.20447542 | AJ13: -0.20447542 | AK13: -0.20447542 | AM13: -358.75136 | AN13: 40.809667 | AO13: 1.7593333 | AP13: 6.1585 | AQ13: 84.2715 | AR13: 79.371833 | AS13: 0.19216229 | AT13: 0.0082842512 | AU13: 0.028998803 | AV13: 0.39681296 | AW13: 0.37374169 | AX13: -68.938484 | AY13: -2.9719863 | AZ13: -10.40336 | BA13: -142.35719 | BB13: -134.08034 | BC13: 1.554127 | BD13: 1.7568392 | BE13: 1.8413026 | BF13: 2.0609075 | BG13: 1.6554831 | BH13: 0.68926848 | BI13: 0.68926848 | BJ13: 0.68926848 | BK13: 0.68926848 | BL13: 0.68926848 | BM13: 2.0346824 | BN13: 2.0346824 | BO13: 2.0346824 | BP13: 2.0346824 | BQ13: 2.0346824 | DB13: -107.91604 | DC13: 3.9457419 | DD13: 2.7939826 | DE13: 3.7939826 | DF13: 4.5697587 | DI13: -46.445585 | DJ13: 27.666667 | DK13: 24.99 | DL13: 0.52541622 | DM13: 0.47458378 | DN13: -24.403264 | DO13: -22.042321 | DP13: 0.73209791 | DQ13: 2.6990598 | DR13: 0.13372814 | DS13: 0.13372814
A14: 43252 | B14: -84.623041 | C14: 27.51 | D14: 6.1134 | E14: 36.454917 | F14: 0.3925608 | G14: 0.087236684 | H14: 0.52020252 | I14: -33.219689 | J14: -7.3822336 | K14: -44.021119 | L14: 1.2679271 | M14: 1.1109456 | N14: 1.3283045 | O14: 0.20754957 | P14: 0.20754957 | Q14: 0.20754957 | R14: 1.5166089 | S14: 1.5166089 | T14: 1.5166089 | V14: -139.29535 | W14: 76.8425 | X14: 52.509 | Y14: 45.595 | Z14: 0.43923428 | AA14: 0.30014319 | AB14: 0.26062253 | AC14: -61.183293 | AD14: -41.80855 | AE14: -36.303507 | AF14: 0.83602768 | AG14: 0.73251949 | AH14: 0.87583852 | AI14: -0.25593927 | AJ14: -0.25593927 | AK14: -0.25593927 | AM14: -318.94905 | AN14: 40.809667 | AO14: 1.77625 | AP14: 6.215 | AQ14: 82.89 | AR14: 80.18175 | AS14: 0.19261412 | AT14: 0.0083835732 | AU14: 0.029333656 | AV14: 0.39122555 | AW14: 0.37844311 | AX14: -61.434089 | AY14: -2.6739327 | AZ14: -9.3559418 | BA14: -124.78102 | BB14: -120.70407 | BC14: 1.3849504 | BD14: 1.5806499 | BE14: 1.6559189 | BF14: 1.806457 | BG14: 1.490327 | BH14: 0.50538082 | BI14: 0.50538082 | BJ14: 0.50538082 | BK14: 0.50538082 | BL14: 0.50538082 | BM14: 1.8906669 | BN14: 1.8906669 | BO14: 1.8906669 | BP14: 1.8906669 | BQ14: 1.8906669 | DB14: -107.91604 | DC14: 3.9457419 | DD14: 2.7578494 | DE14: 3.7578494 | DF14: 4.7196306 | DI14: -47.434754 | DJ14: 28 | DK14: 25.316667 | DL14: 0.52516411 | DM14: 0.47483589 | DN14: -24.911031 | DO14: -22.523724 | DP14: 0.74733092 | DQ14: 2.758007 | DR14: 0.12400006 | DS14: 0.12400006
A15: 43282 | B15: -90.191177 | C15: 27.772 | D15: 6.2463 | E15: 37.449142 | F15: 0.38859653 | G15: 0.087400638 | H15: 0.52400283 | I15: -35.047979 | J15: -7.8827664 | K15: -47.260432 | L15: 1.3377091 | M15: 1.1862703 | N15: 1.4260484 | O15: 0.26198972 | P15: 0.26198972 | Q15: 0.26198972 | R15: 1.5844472 | S15: 1.5844472 | T15: 1.5844472 | V15: -141.82492 | W15: 77.574333 | X15: 53.6505 | Y15: 46.8385 | Z15: 0.43565585 | AA15: 0.3013001 | AB15: 0.26304405 | AC15: -61.786857 | AD15: -42.731863 | AE15: -37.306201 | AF15: 0.84427497 | AG15: 0.74869667 | AH15: 0.90002898 | AI15: -0.25551513 | AJ15: -0.25551513 | AK15: -0.25551513 | AM15: -340.10148 | AN15: 41.696833 | AO15: 1.7931667 | AP15: 6.3845 | AQ15: 88.416 | AR15: 84.231333 | AS15: 0.18738311 | AT15: 0.0080583853 | AU15: 0.028691567 | AV15: 0.39733629 | AW15: 0.37853065 | AX15: -63.729274 | AY15: -2.7406688 | AZ15: -9.7580443 | BA15: -135.13466 | BB15: -128.73883 | BC15: 1.4366922 | BD15: 1.6200998 | BE15: 1.7270875 | BF15: 1.9563469 | BG15: 1.5895318 | BH15: 0.52839601 | BI15: 0.52839601 | BJ15: 0.52839601 | BK15: 0.52839601 | BL15: 0.52839601 | BM15: 1.9189243 | BN15: 1.9189243 | BO15: 1.9189243 | BP15: 1.9189243 | BQ15: 1.9189243 | DB15: -107.91783 | DC15: 3.9458072 | DD15: 2.7224597 | DE15: 3.7224597 | DF15: 4.6736044 | DI15: -48.223542 | DJ15: 28.333333 | DK15: 25.561667 | DL15: 0.52571358 | DM15: 0.47428642 | DN15: -25.351771 | DO15: -22.871771 | DP15: 0.76055312 | DQ15: 2.800625 | DR15: 0.11760767 | DS15: 0.11760767 | DV15: -51.557244 | DW15: 1.726247 | DX15: 0.81318199 | DY15: 0.93078965 | DZ15: 1.0424207
A16: 43313 | B16: -103.28642 | C16: 28.034 | D16: 6.2463 | E16: 37.449142 | F16: 0.39082975 | G16: 0.087081397 | H16: 0.52208885 | I16: -40.367407 | J16: -8.9943259 | K16: -53.924689 | L16: 1.5407407 | M16: 1.3535479 | N16: 1.6271374 | O16: 0.4399446 | P16: 0.4399446 | Q16: 0.4399446 | R16: 1.810707 | S16: 1.810707 | T16: 1.810707 | V16: -142.18487 | W16: 78.306167 | X16: 53.6505 | Y16: 46.8385 | Z16: 0.43796579 | AA16: 0.30006684 | AB16: 0.26196737 | AC16: -62.27211 | AD16: -42.664964 | AE16: -37.247797 | AF16: 0.85090562 | AG16: 0.74752456 | AH16: 0.89861995 | AI16: -0.25748376 | AJ16: -0.25748376 | AK16: -0.25748376 | AM16: -388.41128 | AN16: 41.696833 | AO16: 1.8100833 | AP16: 6.3845 | AQ16: 91.179 | AR16: 86.661083 | AS16: 0.18309647 | AT16: 0.0079483222 | AU16: 0.028035208 | AV16: 0.40037939 | AW16: 0.38054061 | AX16: -71.116733 | AY16: -3.087218 | AZ16: -10.889191 | BA16: -155.51187 | BB16: -147.80626 | BC16: 1.6032328 | BD16: 1.8249564 | BE16: 1.9272904 | BF16: 2.2513481 | BG16: 1.8249564 | BH16: 0.70556676 | BI16: 0.70556676 | BJ16: 0.70556676 | BK16: 0.70556676 | BL16: 0.70556676 | BM16: 2.1447225 | BN16: 2.1447225 | BO16: 2.1447225 | BP16: 2.1447225 | BQ16: 2.1447225 | DB16: -107.93959 | DC16: 3.9466028 | DD16: 2.6884138 | DE16: 3.6884138 | DF16: 4.6381205 | DI16: -49.528973 | DJ16: 28 | DK16: 25.235 | DL16: 0.52596976 | DM16: 0.47403024 | DN16: -26.050742 | DO16: -23.478231 | DP16: 0.78152225 | DQ16: 2.8748854 | DR16: 0.074825439 | DS16: 0.074825439 | DV16: -52.320752 | DW16: 1.7518109 | DX16: 0.76388901 | DY16: 0.83871445 | DZ16: 1.0397265
A17: 43344 | B17: -101.19758 | C17: 29.082 | D17: 6.1134 | E17: 37.78055 | F17: 0.39851485 | G17: 0.083772805 | H17: 0.51771234 | I17: -40.328737 | J17: -8.4776047 | K17: -52.391234 | L17: 1.5392648 | M17: 1.275787 | N17: 1.5808665 | O17: 0.38672501 | P17: 0.38672501 | Q17: 0.38672501 | R17: 1.7040215 | S17: 1.7040215 | T17: 1.7040215 | V17: -147.29332 | W17: 81.2335 | X17: 52.509 | Y17: 47.253 | Z17: 0.44881503 | AA17: 0.29011219 | AB17: 0.26107279 | AC17: -66.107456 | AD17: -42.731587 | AE17: -38.454278 | AF17: 0.90331299 | AG17: 0.74869185 | AH17: 0.92772685 | AI17: -0.22880996 | AJ17: -0.22880996 | AK17: -0.22880996 | AM17: -379.88437 | AN17: 40.809667 | AO17: 1.87775 | AP17: 6.441 | AQ17: 92.5605 | AR17: 91.520583 | AS17: 0.17499144 | AT17: 0.0080517732 | AU17: 0.027618943 | AV17: 0.3968985 | AW17: 0.39243934 | AX17: -66.476514 | AY17: -3.0587428 | AZ17: -10.492005 | BA17: -150.77554 | BB17: -149.08157 | BC17: 1.4986251 | BD17: 1.8081238 | BE17: 1.856992 | BF17: 2.1827801 | BG17: 1.8407026 | BH17: 0.62894037 | BI17: 0.62894037 | BJ17: 0.62894037 | BK17: 0.62894037 | BL17: 0.62894037 | BM17: 2.0016582 | BN17: 2.0016582 | BO17: 2.0016582 | BP17: 2.0016582 | BQ17: 2.0016582 | DB17: -107.94614 | DC17: 3.9468425 | DD17: 2.555714 | DE17: 3.555714 | DF17: 4.3692968 | DI17: -50.235639 | DJ17: 28 | DK17: 25.806667 | DL17: 0.52038161 | DM17: 0.47961839 | DN17: -26.141703 | DO17: -24.093936 | DP17: 0.78425109 | DQ17: 2.9502779 | DR17: 0.071085538 | DS17: 0.071085538 | DV17: -52.743984 | DW17: 1.7659816 | DX17: 0.78937311 | DY17: 0.86045865 | DZ17: 1.0344171
A18: 43374 | B18: -107.09016 | C18: 29.082 | D18: 5.5818 | E18: 36.786325 | F18: 0.40702518 | G18: 0.078121627 | H18: 0.51485319 | I18: -43.58839 | J18: -8.3660573 | K18: -55.135709 | L18: 1.663679 | M18: 1.2590003 | N18: 1.663679 | O18: 0.49880993 | P18: 0.49880993 | Q18: 0.49880993 | R18: 1.8415111 | S18: 1.8415111 | T18: 1.8415111 | V18: -142.58427 | W18: 81.2335 | X18: 47.943 | Y18: 46.0095 | Z18: 0.46369858 | AA18: 0.27366913 | AB18: 0.26263229 | AC18: -66.116123 | AD18: -39.020913 | AE18: -37.447233 | AF18: 0.90343143 | AG18: 0.68367784 | AH18: 0.90343143 | AI18: -0.22864887 | AJ18: -0.22864887 | AK18: -0.22864887 | AM18: -400.98465 | AN18: 37.261 | AO18: 1.87775 | AP18: 6.2715 | AQ18: 89.7975 | AR18: 91.520583 | AS18: 0.16434205 | AT18: 0.008281938 | AU18: 0.027660857 | AV18: 0.39605769 | AW18: 0.40365746 | AX18: -65.898641 | AY18: -3.32093 | AZ18: -11.091579 | BA18: -158.81306 | BB18: -161.86045 | BC18: 1.4855978 | BD18: 1.9631113 | BE18: 1.9631113 | BF18: 2.2991394 | BG18: 1.9984827 | BH18: 0.76856878 | BI18: 0.76856878 | BJ18: 0.76856878 | BK18: 0.76856878 | BL18: 0.76856878 | BM18: 2.17295 | BN18: 2.17295 | BO18: 2.17295 | BP18: 2.17295 | BQ18: 2.17295 | DB18: -107.96373 | DC18: 3.9474855 | DD18: 2.5562932 | DE18: 3.5562932 | DF18: 4.3694357 | DI18: -50.641981 | DJ18: 28.333333 | DK18: 25.316667 | DL18: 0.52811432 | DM18: 0.47188568 | DN18: -26.744756 | DO18: -23.897226 | DP18: 0.80234267 | DQ18: 2.9261909 | DR18: 0.059397731 | DS18: 0.059397731 | DV18: -53.647984 | DW18: 1.7962495 | DX18: 0.7258182 | DY18: 0.78521593 | DZ18: 1.0615785
A19: 43405 | B19: -91.969223 | C19: 28.82 | D19: 5.1831 | E19: 35.460692 | F19: 0.41489241 | G19: 0.074615852 | H19: 0.51049174 | I19: -38.157333 | J19: -6.862362 | K19: -46.949529 | L19: 1.4563867 | M19: 1.0327106 | N19: 1.4166671 | O19: 0.32398795 | P19: 0.32398795 | Q19: 0.32398795 | R19: 1.8713995 | S19: 1.8713995 | T19: 1.8713995 | V19: -119.82799 | W19: 80.501667 | X19: 44.5185 | Y19: 44.3515 | Z19: 0.47529595 | AA19: 0.26284503 | AB19: 0.26185903 | AC19: -56.953759 | AD19: -31.496192 | AE19: -31.378042 | AF19: 0.77823402 | AG19: 0.55183867 | AH19: 0.75700945 | AI19: -0.41345659 | AJ19: -0.41345659 | AK19: -0.41345659 | AM19: -344.41394 | AN19: 34.5995 | AO19: 1.8608333 | AP19: 6.0455 | AQ19: 84.2715 | AR19: 89.90075 | AS19: 0.15968159 | AT19: 0.008588009 | AU19: 0.027900838 | AV19: 0.38892489 | AW19: 0.41490468 | AX19: -54.996564 | AY19: -2.95783 | AZ19: -9.6094374 | BA19: -133.95115 | BB19: -142.89895 | BC19: 1.2398249 | BD19: 1.7484709 | BE19: 1.7007854 | BF19: 1.9392132 | BG19: 1.7643661 | BH19: 0.58951904 | BI19: 0.58951904 | BJ19: 0.58951904 | BK19: 0.58951904 | BL19: 0.58951904 | BM19: 2.2467162 | BN19: 2.2467162 | BO19: 2.2467162 | BP19: 2.2467162 | BQ19: 2.2467162 | DB19: -107.94823 | DC19: 3.9469188 | DD19: 2.588108 | DE19: 3.588108 | DF19: 5.0716349 | DI19: -48.789601 | DJ19: 29 | DK19: 24.908333 | DL19: 0.53795022 | DM19: 0.46204978 | DN19: -26.246377 | DO19: -22.543224 | DP19: 0.78739131 | DQ19: 2.7603948 | DR19: 0.10491441 | DS19: 0.10491441 | DV19: -53.466359 | DW19: 1.7901683 | DX19: 0.70375046 | DY19: 0.80866487 | DZ19: 1.0855068
A20: 43435 | B20: -81.618162 | C20: 28.558 | D20: 4.71795 | E20: 34.797875 | F20: 0.41951514 | G20: 0.069306374 | H20: 0.51117849 | I20: -34.240054 | J20: -5.6566589 | K20: -41.721449 | L20: 1.3068723 | M20: 0.85126544 | N20: 1.2589137 | O20: 0.19896542 | P20: 0.19896542 | Q20: 0.19896542 | R20: 1.7507612 | S20: 1.7507612 | T20: 1.7507612 | V20: -112.18504 | W20: 79.769833 | X20: 40.52325 | Y20: 43.5225 | Z20: 0.48694899 | AA20: 0.24737115 | AB20: 0.26567985 | AC20: -54.628393 | AD20: -27.751343 | AE20: -29.805305 | AF20: 0.74645948 | AG20: 0.4862259 | AH20: 0.71906647 | AI20: -0.46022661 | AJ20: -0.46022661 | AK20: -0.46022661 | AM20: -305.5274 | AN20: 31.494417 | AO20: 1.8439167 | AP20: 5.9325 | AQ20: 77.364 | AR20: 88.280917 | AS20: 0.15369447 | AT20: 0.0089984136 | AU20: 0.028950923 | AV20: 0.37754053 | AW20: 0.43081567 | AX20: -46.95787 | AY20: -2.7492619 | AZ20: -8.8453001 | BA20: -115.34898 | BB20: -131.62599 | BC20: 1.0586031 | BD20: 1.6251795 | BE20: 1.5655398 | BF20: 1.6699092 | BG20: 1.6251795 | BH20: 0.49099032 | BI20: 0.49099032 | BJ20: 0.49099032 | BK20: 0.49099032 | BL20: 0.49099032 | BM20: 2.1771837 | BN20: 2.1771837 | BO20: 2.1771837 | BP20: 2.1771837 | BQ20: 2.1771837 | DB20: -107.93959 | DC20: 3.9466028 | DD20: 2.6207365 | DE20: 3.6207365 | DF20: 5.2870958 | DI20: -47.678169 | DJ20: 29.666667 | DK20: 24.99 | DL20: 0.54278222 | DM20: 0.45721778 | DN20: -25.878862 | DO20: -21.799307 | DP20: 0.77636587 | DQ20: 2.6693029 | DR20: 0.14636672 | DS20: 0.14636672 | DV20: -53.39079 | DW20: 1.7876381 | DX20: 0.71175591 | DY20: 0.85812263 | DZ20: 1.09822
A21: 43466 | B21: -84.954404 | C21: 28.558 | D21: 4.3857 | E21: 33.80365 | F21: 0.42785219 | G21: 0.065705979 | H21: 0.50644183 | I21: -36.347928 | J21: -5.5820123 | K21: -43.024463 | L21: 1.3873255 | M21: 0.84003195 | N21: 1.2982312 | O21: 0.27277568 | P21: 0.27277568 | Q21: 0.27277568 | R21: 1.8558278 | S21: 1.8558278 | T21: 1.8558278 | V21: -109.53905 | W21: 79.769833 | X21: 37.6695 | Y21: 42.279 | Z21: 0.49944068 | AA21: 0.23584957 | AB21: 0.26470975 | AC21: -54.708256 | AD21: -25.834737 | AE21: -28.996054 | AF21: 0.74755076 | AG21: 0.45264541 | AH21: 0.69954291 | AI21: -0.45809497 | AJ21: -0.45809497 | AK21: -0.45809497 | AM21: -319.94815 | AN21: 29.2765 | AO21: 1.8439167 | AP21: 5.763 | AQ21: 71.838 | AR21: 89.090833 | AS21: 0.14800145 | AT21: 0.0093215494 | AU21: 0.029133686 | AV21: 0.36316254 | AW21: 0.45038077 | AX21: -47.352791 | AY21: -2.9824125 | AZ21: -9.321269 | BA21: -116.19318 | BB21: -144.09849 | BC21: 1.0675061 | BD21: 1.7630025 | BE21: 1.6497821 | BF21: 1.6821308 | BG21: 1.7791768 | BH21: 0.61743346 | BI21: 0.61743346 | BJ21: 0.61743346 | BK21: 0.61743346 | BL21: 0.61743346 | BM21: 2.3583716 | BN21: 2.3583716 | BO21: 2.3583716 | BP21: 2.3583716 | BQ21: 2.3583716 | CU21: -76.290633 | CV21: 13.443333 | CW21: 2.2699916 | CX21: 4.6749789 | CY21: 6.6374257 | DB21: -107.91932 | DC21: 3.9458617 | DD21: 2.6200566 | DE21: 3.6200566 | DF21: 5.2783864 | DI21: -46.516111 | DJ21: 29.333333 | DK21: 25.071667 | DL21: 0.53916613 | DM21: 0.46083387 | DN21: -25.079911 | DO21: -21.436199 | DP21: 0.75239734 | DQ21: 2.6248407 | DR21: 0.16959478 | DS21: 0.16959478 | DV21: -53.102217 | DW21: 1.777976 | DX21: 0.72668245 | DY21: 0.89627723 | DZ21: 1.0876227
A22: 43497 | B22: -84.17092 | C22: 28.034 | D22: 4.3857 | E22: 33.472242 | F22: 0.42545415 | G22: 0.066558974 | H22: 0.50798688 | I22: -35.810867 | J22: -5.60233 | K22: -42.757723 | L22: 1.366827 | M22: 0.84308955 | N22: 1.2901825 | O22: 0.27740841 | P22: 0.27740841 | Q22: 0.27740841 | R22: 1.7706595 | S22: 1.7706595 | T22: 1.7706595 | V22: -113.87076 | W22: 78.306167 | X22: 37.6695 | Y22: 41.8645 | Z22: 0.49611052 | AA22: 0.23865598 | AB22: 0.2652335 | AC22: -56.492484 | AD22: -27.175939 | AE22: -30.202341 | AF22: 0.771931 | AG22: 0.47614435 | AH22: 0.72864515 | AI22: -0.38613425 | AJ22: -0.38613425 | AK22: -0.38613425 | AM22: -320.09883 | AN22: 29.2765 | AO22: 1.8100833 | AP22: 5.7065 | AQ22: 67.6935 | AR22: 86.661083 | AS22: 0.15316169 | AT22: 0.009469555 | AU22: 0.029853883 | AV22: 0.35414243 | AW22: 0.45337244 | AX22: -49.026878 | AY22: -3.0311934 | AZ22: -9.5561927 | BA22: -113.36058 | BB22: -145.12398 | BC22: 1.1052462 | BD22: 1.7918385 | BE22: 1.6913615 | BF22: 1.6411231 | BG22: 1.7918385 | BH22: 0.67461539 | BI22: 0.67461539 | BJ22: 0.67461539 | BK22: 0.67461539 | BL22: 0.67461539 | BM22: 2.3212418 | BN22: 2.3212418 | BO22: 2.3212418 | BP22: 2.3212418 | BQ22: 2.3212418 | CU22: -73.24968 | CV22: 13.443333 | CW22: 2.1795095 | CX22: 4.4487736 | CY22: 6.2860821 | DB22: -107.88087 | DC22: 3.9444559 | DD22: 2.6864074 | DE22: 3.6864074 | DF22: 5.1098556 | DI22: -46.368002 | DJ22: 28.666667 | DK22: 24.826667 | DL22: 0.53589232 | DM22: 0.46410768 | DN22: -24.848256 | DO22: -21.519746 | DP22: 0.74544768 | DQ22: 2.6350709 | DR22: 0.15366916 | DS22: 0.15366916 | DV22: -51.771452 | DW22: 1.7334191 | DX22: 0.75375933 | DY22: 0.90742848 | DZ22: 1.1006381
A23: 43525 | B23: -81.74968 | C23: 28.296 | D23: 4.6515 | E23: 34.135058 | F23: 0.4218086 | G23: 0.069339932 | H23: 0.50885147 | I23: -34.482718 | J23: -5.6685172 | K23: -41.598445 | L23: 1.3161343 | M23: 0.85304999 | N23: 1.2552021 | O23: 0.21864285 | P23: 0.21864285 | Q23: 0.21864285 | R23: 1.6635745 | S23: 1.6635745 | T23: 1.6635745 | V23: -118.44077 | W23: 79.038 | X23: 39.9525 | Y23: 42.6935 | Z23: 0.48884243 | AA23: 0.24710237 | AB23: 0.26405519 | AC23: -57.898876 | AD23: -29.266996 | AE23: -31.274901 | AF23: 0.79114838 | AG23: 0.51278136 | AH23: 0.75452114 | AI23: -0.36510422 | AJ23: -0.36510422 | AK23: -0.36510422 | AM23: -312.86247 | AN23: 31.050833 | AO23: 1.827 | AP23: 5.8195 | AQ23: 67.00275 | AR23: 85.851167 | AS23: 0.16210196 | AT23: 0.0095379174 | AU23: 0.030380903 | AV23: 0.3497902 | AW23: 0.44818902 | AX23: -50.71562 | AY23: -2.9840564 | AZ23: -9.5050444 | BA23: -109.43623 | BB23: -140.22152 | BC23: 1.1433166 | BD23: 1.7639742 | BE23: 1.6823087 | BF23: 1.5843102 | BG23: 1.731308 | BH23: 0.63330946 | BI23: 0.63330946 | BJ23: 0.63330946 | BK23: 0.63330946 | BL23: 0.63330946 | BM23: 2.2296376 | BN23: 2.2296376 | BO23: 2.2296376 | BP23: 2.2296376 | BQ23: 2.2296376 | CU23: -71.293098 | CV23: 13.10725 | CW23: 2.1212923 | CX23: 4.439211 | CY23: 6.4369543 | DB23: -107.85613 | DC23: 3.9435514 | DD23: 2.6514365 | DE23: 3.6514365 | DF23: 4.9845914 | DI23: -45.403129 | DJ23: 28.333333 | DK23: 25.398333 | DL23: 0.52731164 | DM23: 0.47268836 | DN23: -23.941599 | DO23: -21.461531 | DP23: 0.71824796 | DQ23: 2.6279425 | DR23: 0.18343532 | DS23: 0.18343532 | DV23: -50.959678 | DW23: 1.7062392 | DX23: 0.82272212 | DY23: 1.0061574 | DZ23: 1.1126958
A24: 43556 | B24: -81.591768 | C24: 28.296 | D24: 4.71795 | E24: 34.135058 | F24: 0.42139118 | G24: 0.070260904 | H24: 0.50834791 | I24: -34.382052 | J24: -5.7327114 | K24: -41.477005 | L24: 1.3122921 | M24: 0.86271052 | N24: 1.2515378 | O24: 0.21508523 | P24: 0.21508523 | Q24: 0.21508523 | R24: 1.5988943 | S24: 1.5988943 | T24: 1.5988943 | V24: -123.30606 | W24: 79.038 | X24: 40.52325 | Y24: 42.6935 | Z24: 0.48712287 | AA24: 0.24975078 | AB24: 0.26312635 | AC24: -60.065201 | AD24: -30.795784 | AE24: -32.445073 | AF24: 0.82074973 | AG24: 0.53956695 | AH24: 0.78275206 | AI24: -0.31587006 | AJ24: -0.31587006 | AK24: -0.31587006 | AM24: -312.89284 | AN24: 31.494417 | AO24: 1.827 | AP24: 5.8195 | AQ24: 67.00275 | AR24: 82.6115 | AS24: 0.16685327 | AT24: 0.0096792052 | AU24: 0.030830944 | AV24: 0.35497174 | AW24: 0.43766484 | AX24: -52.207193 | AY24: -3.028554 | AZ24: -9.6467816 | BA24: -111.06811 | BB24: -136.94219 | BC24: 1.1769422 | BD24: 1.7902782 | BE24: 1.707395 | BF24: 1.6079351 | BG24: 1.6908183 | BH24: 0.65766502 | BI24: 0.65766502 | BJ24: 0.65766502 | BK24: 0.65766502 | BL24: 0.65766502 | BM24: 2.1812718 | BN24: 2.1812718 | BO24: 2.1812718 | BP24: 2.1812718 | BQ24: 2.1812718 | CU24: -70.680193 | CV24: 13.10725 | CW24: 2.1030556 | CX24: 4.3924502 | CY24: 6.5478793 | DB24: -107.84838 | DC24: 3.9432681 | DD24: 2.6511742 | DE24: 3.6511742 | DF24: 4.8044708 | DI24: -44.457514 | DJ24: 28.666667 | DK24: 25.316667 | DL24: 0.5310281 | DM24: 0.4689719 | DN24: -23.608189 | DO24: -20.849325 | DP24: 0.70824567 | DQ24: 2.5529786 | DR24: 0.21426793 | DS24: 0.21426793 | DV24: -48.696634 | DW24: 1.6304677 | DX24: 0.90129499 | DY24: 1.1155629 | DZ24: 1.1266808
A25: 43586 | B25: -81.239505 | C25: 28.558 | D25: 4.98375 | E25: 34.135058 | F25: 0.42197616 | G25: 0.073640441 | H25: 0.50438339 | I25: -34.281135 | J25: -5.9825129 | K25: -40.975857 | L25: 1.3084403 | M25: 0.90030292 | N25: 1.236416 | O25: 0.2004039 | P25: 0.2004039 | Q25: 0.2004039 | R25: 1.6463154 | S25: 1.6463154 | T25: 1.6463154 | V25: -120.50562 | W25: 79.769833 | X25: 42.80625 | Y25: 42.6935 | Z25: 0.48266494 | AA25: 0.25900864 | AB25: 0.25832642 | AC25: -58.163836 | AD25: -31.211996 | AE25: -31.129785 | AF25: 0.79476888 | AG25: 0.54685932 | AH25: 0.75102014 | AI25: -0.37146788 | AJ25: -0.37146788 | AK25: -0.37146788 | AM25: -312.96058 | AN25: 33.26875 | AO25: 1.8439167 | AP25: 5.8195 | AQ25: 67.00275 | AR25: 80.18175 | AS25: 0.17685169 | AT25: 0.0098019846 | AU25: 0.03093559 | AV25: 0.35617657 | AW25: 0.42623416 | AX25: -55.347607 | AY25: -3.0676348 | AZ25: -9.6816201 | BA25: -111.46923 | BB25: -133.39449 | BC25: 1.2477387 | BD25: 1.8133802 | BE25: 1.7135611 | BF25: 1.613742 | BG25: 1.647015 | BH25: 0.66365154 | BI25: 0.66365154 | BJ25: 0.66365154 | BK25: 0.66365154 | BL25: 0.66365154 | BM25: 2.2816447 | BN25: 2.2816447 | BO25: 2.2816447 | BP25: 2.2816447 | BQ25: 2.2816447 | CU25: -69.312942 | CV25: 13.10725 | CW25: 2.0623737 | CX25: 4.2881377 | CY25: 6.6014342 | DB25: -107.8311 | DC25: 3.942636 | DD25: 2.6170973 | DE25: 3.6170973 | DF25: 4.9607328 | DI25: -43.505509 | DJ25: 28.666667 | DK25: 25.643333 | DL25: 0.52783404 | DM25: 0.47216596 | DN25: -22.963689 | DO25: -20.541821 | DP25: 0.68891066 | DQ25: 2.515325 | DR25: 0.24834764 | DS25: 0.24834764 | DV25: -47.837353 | DW25: 1.6016971 | DX25: 0.96042063 | DY25: 1.2087683 | DZ25: 1.1469361
A26: 43617 | B26: -80.783991 | C26: 28.82 | D26: 5.24955 | E26: 34.466467 | F26: 0.42050883 | G26: 0.076595493 | H26: 0.50289568 | I26: -33.970381 | J26: -6.1876896 | K26: -40.62592 | L26: 1.2965794 | M26: 0.93117978 | N26: 1.2258569 | O26: 0.17870858 | P26: 0.17870858 | Q26: 0.17870858 | R26: 1.8477243 | S26: 1.8477243 | T26: 1.8477243 | V26: -107.61717 | W26: 80.501667 | X26: 45.08925 | Y26: 43.108 | Z26: 0.47719137 | AA26: 0.26727646 | AB26: 0.25553217 | AC26: -51.353984 | AD26: -28.763536 | AE26: -27.499648 | AF26: 0.70171692 | AG26: 0.50396034 | AH26: 0.66344146 | AI26: -0.56758368 | AJ26: -0.56758368 | AK26: -0.56758368 | AM26: -313.04818 | AN26: 35.043083 | AO26: 1.8608333 | AP26: 5.876 | AQ26: 64.9305 | AR26: 77.752 | AS26: 0.18894978 | AT26: 0.010033479 | AU26: 0.031682969 | AV26: 0.35010058 | AW26: 0.41923319 | AX26: -59.150386 | AY26: -3.1409625 | AZ26: -9.9182959 | BA26: -109.59835 | BB26: -131.24019 | BC26: 1.3334673 | BD26: 1.8567266 | BE26: 1.7554506 | BF26: 1.5866573 | BG26: 1.6204159 | BH26: 0.68793326 | BI26: 0.68793326 | BJ26: 0.68793326 | BK26: 0.68793326 | BL26: 0.68793326 | BM26: 2.6459766 | BN26: 2.6459766 | BO26: 2.6459766 | BP26: 2.6459766 | BQ26: 2.6459766 | CU26: -67.544946 | CV26: 13.10725 | CW26: 2.0097678 | CX26: 4.1532508 | CY26: 6.6863239 | DB26: -107.80874 | DC26: 3.9418187 | DD26: 2.5834716 | DE26: 3.5834716 | DF26: 5.6173915 | DI26: -42.555034 | DJ26: 29 | DK26: 26.215 | DL26: 0.5252196 | DM26: 0.4747804 | DN26: -22.350738 | DO26: -20.204296 | DP26: 0.67052214 | DQ26: 2.4739955 | DR26: 0.29749632 | DS26: 0.29749632 | DV26: -47.352038 | DW26: 1.5854477 | DX26: 1.0246647 | DY26: 1.322161 | DZ26: 1.1509995
A27: 43647 | B27: -73.133657 | C27: 28.296 | D27: 5.38245 | E27: 33.140833 | F27: 0.42347057 | G27: 0.080552346 | H27: 0.49597708 | I27: -30.969951 | J27: -5.8910876 | K27: -36.272618 | L27: 1.1820592 | M27: 0.88654441 | N27: 1.0944993 | O27: 0.094499273 | P27: 0.094499273 | Q27: 0.094499273 | R27: 1.6568518 | S27: 1.6568518 | T27: 1.6568518 | V27: -110.13269 | W27: 79.038 | X27: 46.23075 | Y27: 41.45 | Z27: 0.47407985 | AA27: 0.27729784 | AB27: 0.24862231 | AC27: -52.211691 | AD27: -30.539559 | AE27: -27.381444 | AF27: 0.71343691 | AG27: 0.53507768 | AH27: 0.66058973 | AI27: -0.51379888 | AJ27: -0.51379888 | AK27: -0.51379888 | AM27: -283.71147 | AN27: 35.93025 | AO27: 1.827 | AP27: 5.65 | AQ27: 62.1675 | AR27: 72.082583 | AS27: 0.20224468 | AT27: 0.010283842 | AU27: 0.031802796 | AV27: 0.34992926 | AW27: 0.40573942 | AX27: -57.379135 | AY27: -2.917644 | AZ27: -9.0228182 | BA27: -99.278947 | BB27: -115.11293 | BC27: 1.2935368 | BD27: 1.7247157 | BE27: 1.596959 | BF27: 1.4372631 | BG27: 1.4212935 | BH27: 0.59695898 | BI27: 0.59695898 | BJ27: 0.59695898 | BK27: 0.59695898 | BL27: 0.59695898 | BM27: 2.4174747 | BN27: 2.4174747 | BO27: 2.4174747 | BP27: 2.4174747 | BQ27: 2.4174747 | CU27: -67.615666 | CV27: 11.762917 | CW27: 2.011872 | CX27: 4.7482058 | CY27: 7.4253379 | DB27: -107.80964 | DC27: 3.9418514 | DD27: 2.6498624 | DE27: 3.6498624 | DF27: 5.5251576 | DI27: -41.2794 | DJ27: 28.333333 | DK27: 24.99 | DL27: 0.53134963 | DM27: 0.46865037 | DN27: -21.933794 | DO27: -19.345606 | DP27: 0.65801382 | DQ27: 2.3688498 | DR27: 0.29176618 | DS27: 0.29176618 | DV27: -47.298641 | DW27: 1.5836598 | DX27: 0.93223312 | DY27: 1.2239993 | DZ27: 1.1657838
A28: 43678 | B28: -71.252959 | C28: 27.51 | D28: 5.316 | E28: 31.483792 | F28: 0.42777312 | G28: 0.082662373 | H28: 0.48956451 | I28: -30.480101 | J28: -5.8899387 | K28: -34.88292 | L28: 1.1633626 | M28: 0.88637152 | N28: 1.0525662 | O28: 0.1079644 | P28: 0.1079644 | Q28: 0.1079644 | R28: 1.7055039 | S28: 1.7055039 | T28: 1.7055039 | V28: -105.1638 | W28: 76.8425 | X28: 45.66 | Y28: 39.3775 | Z28: 0.47468804 | AA28: 0.28206079 | AB28: 0.24325117 | AC28: -49.92 | AD28: -29.662585 | AE28: -25.581219 | AF28: 0.68212253 | AG28: 0.5197124 | AH28: 0.61715848 | AI28: -0.53931289 | AJ28: -0.53931289 | AK28: -0.53931289 | AM28: -276.37116 | AN28: 35.486667 | AO28: 1.77625 | AP28: 5.3675 | AQ28: 58.71375 | AR28: 69.652833 | AS28: 0.20752801 | AT28: 0.010387609 | AU28: 0.03138944 | AV28: 0.34336129 | AW28: 0.40733366 | AX28: -57.354757 | AY28: -2.8708356 | AZ28: -8.6751359 | BA28: -94.895158 | BB28: -112.57528 | BC28: 1.2929872 | BD28: 1.6970457 | BE28: 1.5354223 | BF28: 1.3737989 | BG28: 1.3899612 | BH28: 0.61623399 | BI28: 0.61623399 | BJ28: 0.61623399 | BK28: 0.61623399 | BL28: 0.61623399 | BM28: 2.4878898 | BN28: 2.4878898 | BO28: 2.4878898 | BP28: 2.4878898 | BQ28: 2.4878898 | CU28: -67.757106 | CV28: 11.426833 | CW28: 2.0160805 | CX28: 4.9296486 | CY28: 7.8966851 | DB28: -107.81142 | DC28: 3.9419168 | DD28: 2.7542065 | DE28: 3.7542065 | DF28: 5.7788984 | DI28: -40.403615 | DJ28: 28 | DK28: 25.806667 | DL28: 0.52038161 | DM28: 0.47961839 | DN28: -21.025298 | DO28: -19.378317 | DP28: 0.63075895 | DQ28: 2.3728551 | DR28: 0.33172902 | DS28: 0.33172902 | DV28: -47.166382 | DW28: 1.5792315 | DX28: 1.0009732 | DY28: 1.3327022 | DZ28: 1.1728294
A29: 43709 | B29: -69.657717 | C29: 26.462 | D29: 5.38245 | E29: 29.82675 | F29: 0.42908197 | G29: 0.087276557 | H29: 0.48364147 | I29: -29.888871 | J29: -6.0794857 | K29: -33.689361 | L29: 1.1407966 | M29: 0.91489627 | N29: 1.0165514 | O29: 0.12950157 | P29: 0.12950157 | Q29: 0.12950157 | R29: 1.6866827 | S29: 1.6866827 | T29: 1.6866827 | V29: -105.43836 | W29: 73.915167 | X29: 46.23075 | Y29: 37.305 | Z29: 0.46944894 | AA29: 0.29362008 | AB29: 0.23693098 | AC29: -49.497926 | AD29: -30.958819 | AE29: -24.981614 | AF29: 0.67635518 | AG29: 0.54242346 | AH29: 0.60269273 | AI29: -0.49329825 | AJ29: -0.49329825 | AK29: -0.49329825 | AM29: -268.97596 | AN29: 35.93025 | AO29: 1.7085833 | AP29: 5.085 | AQ29: 57.33225 | AR29: 67.223083 | AS29: 0.21479214 | AT29: 0.010213964 | AU29: 0.030398286 | AV29: 0.34273395 | AW29: 0.40186166 | AX29: -57.773921 | AY29: -2.7473107 | AZ29: -8.1764082 | BA29: -92.187193 | BB29: -108.09112 | BC29: 1.3024367 | BD29: 1.624026 | BE29: 1.4471519 | BF29: 1.3345956 | BG29: 1.3345956 | BH29: 0.60794654 | BI29: 0.60794654 | BJ29: 0.60794654 | BK29: 0.60794654 | BL29: 0.60794654 | BM29: 2.4011438 | BN29: 2.4011438 | BO29: 2.4011438 | BP29: 2.4011438 | BQ29: 2.4011438 | CU29: -69.00649 | CV29: 11.09075 | CW29: 2.0532553 | CX29: 5.2219859 | CY29: 8.2868077 | DB29: -107.82722 | DC29: 3.9424944 | DD29: 2.9034598 | DE29: 3.9034598 | DF29: 5.8290296 | DI29: -39.847812 | DJ29: 28 | DK29: 25.071667 | DL29: 0.52758848 | DM29: 0.47241152 | DN29: -21.023247 | DO29: -18.824566 | DP29: 0.63069741 | DQ29: 2.3050489 | DR29: 0.33185897 | DS29: 0.33185897 | DV29: -47.751751 | DW29: 1.5988309 | DX29: 0.92015299 | DY29: 1.252012 | DZ29: 1.2031752
A30: 43739 | B30: -66.339689 | C30: 26.462 | D30: 4.9173 | E30: 29.163933 | F30: 0.43707609 | G30: 0.081219646 | H30: 0.48170426 | I30: -28.995492 | J30: -5.388086 | K30: -31.956111 | L30: 1.1066982 | M30: 0.81084816 | N30: 0.96425187 | O30: 0.095740761 | P30: 0.095740761 | Q30: 0.095740761 | R30: 1.5795367 | S30: 1.5795367 | T30: 1.5795367 | V30: -105.87868 | W30: 73.915167 | X30: 42.2355 | Y30: 36.476 | Z30: 0.48428737 | AA30: 0.27672425 | AB30: 0.23898838 | AC30: -51.275708 | AD30: -29.299199 | AE30: -25.303775 | AF30: 0.70064734 | AG30: 0.51334558 | AH30: 0.61046501 | AI30: -0.44152406 | AJ30: -0.44152406 | AK30: -0.44152406 | AM30: -254.21007 | AN30: 32.825167 | AO30: 1.7085833 | AP30: 4.972 | AQ30: 58.71375 | AR30: 69.652833 | AS30: 0.19553649 | AT30: 0.010177873 | AU30: 0.029617745 | AV30: 0.34975239 | AW30: 0.4149155 | AX30: -49.707345 | AY30: -2.5873179 | AZ30: -7.5291292 | BA30: -88.910581 | BB30: -105.4757 | BC30: 1.1205864 | BD30: 1.529449 | BE30: 1.3325892 | BF30: 1.2871601 | BG30: 1.3023031 | BH30: 0.51430595 | BI30: 0.51430595 | BJ30: 0.51430595 | BK30: 0.51430595 | BL30: 0.51430595 | BM30: 2.1829085 | BN30: 2.1829085 | BO30: 2.1829085 | BP30: 2.1829085 | BQ30: 2.1829085 | CU30: -71.010218 | CV30: 10.418583 | CW30: 2.1128753 | CX30: 5.8157269 | CY30: 9.4004606 | DB30: -107.85256 | DC30: 3.9434207 | DD30: 2.9043769 | DE30: 3.9043769 | DF30: 5.6282532 | DI30: -38.962538 | DJ30: 28.666667 | DK30: 25.071667 | DL30: 0.53344912 | DM30: 0.46655088 | DN30: -20.784532 | DO30: -18.178006 | DP30: 0.62353595 | DQ30: 2.2258783 | DR30: 0.37923082 | DS30: 0.37923082 | DV30: -49.12384 | DW30: 1.6447714 | DX30: 0.86652076 | DY30: 1.2457516 | DZ30: 1.2169906
A31: 43770 | B31: -66.39435 | C31: 25.938 | D31: 4.71795 | E31: 28.501117 | F31: 0.43845987 | G31: 0.07975294 | H31: 0.48178719 | I31: -29.111258 | J31: -5.2951446 | K31: -31.987947 | L31: 1.1111167 | M31: 0.7968615 | N31: 0.96521252 | O31: 0.12234014 | P31: 0.12234014 | Q31: 0.12234014 | R31: 1.5037525 | S31: 1.5037525 | T31: 1.5037525 | V31: -110.92528 | W31: 72.4515 | X31: 40.52325 | Y31: 35.647 | Z31: 0.48748921 | AA31: 0.27266029 | AB31: 0.23985049 | AC31: -54.074875 | AD31: -30.244918 | AE31: -26.605482 | AF31: 0.73889604 | AG31: 0.52991534 | AH31: 0.64186929 | AI31: -0.33983665 | AJ31: -0.33983665 | AK31: -0.33983665 | AM31: -254.19956 | AN31: 31.494417 | AO31: 1.67475 | AP31: 4.859 | AQ31: 60.786 | AR31: 70.46275 | AS31: 0.18605264 | AT31: 0.0098935521 | AU31: 0.028704445 | AV31: 0.35909208 | AW31: 0.41625729 | AX31: -47.294499 | AY31: -2.5149366 | AZ31: -7.2966574 | BA31: -91.281049 | BB31: -105.81242 | BC31: 1.066192 | BD31: 1.486662 | BE31: 1.2914438 | BF31: 1.3214774 | BG31: 1.3064606 | BH31: 0.50167883 | BI31: 0.50167883 | BJ31: 0.50167883 | BK31: 0.50167883 | BL31: 0.50167883 | BM31: 2.0120043 | BN31: 2.0120043 | BO31: 2.0120043 | BP31: 2.0120043 | BQ31: 2.0120043 | BT31: -304.98729 | BU31: 0.260925 | BV31: 34.125 | BW31: 224.53358 | BX31: 62.2153 | BY31: 0.00081250926 | BZ31: 0.10626379 | CA31: 0.69918793 | CB31: 0.19373578 | CC31: 0.247805 | CD31: 32.409104 | CE31: 213.24343 | CF31: 59.08695 | CG31: 0.67429932 | CH31: 0.37038976 | CI31: 1.7569771 | CJ31: 0.53184171 | CK31: -0.050282654 | CL31: -0.052944863 | CM31: -0.052944863 | CN31: -0.050282654 | CO31: 1.3202204 | CP31: 1.3202204 | CQ31: 1.3202204 | CR31: 1.3202204 | CU31: -71.222378 | CV31: 10.418583 | CW31: 2.119188 | CX31: 5.8360904 | CY31: 9.5298251 | DB31: -107.85524 | DC31: 3.9435187 | DD31: 2.9833523 | DE31: 3.9833523 | DF31: 5.3370414 | DI31: -38.138385 | DJ31: 28.666667 | DK31: 24.5 | DL31: 0.53918495 | DM31: 0.46081505 | DN31: -20.563643 | DO31: -17.574742 | DP31: 0.6169093 | DQ31: 2.1520092 | DR31: 0.39404609 | DS31: 0.39404609 | DV31: -49.340316 | DW31: 1.6520195 | DX31: 0.81595917 | DY31: 1.2100053 | DZ31: 1.2302222
A32: 43800 | B32: -66.072454 | C32: 25.414 | D32: 4.9173 | E32: 28.169708 | F32: 0.43441986 | G32: 0.084054961 | H32: 0.48152518 | I32: -28.703186 | J32: -5.5537176 | K32: -31.81555 | L32: 1.0955415 | M32: 0.8357739 | N32: 0.96001056 | O32: 0.12942419 | P32: 0.12942419 | Q32: 0.12942419 | R32: 1.4818256 | S32: 1.4818256 | T32: 1.4818256 | V32: -113.15071 | W32: 70.987833 | X32: 42.2355 | Y32: 35.2325 | Z32: 0.47817477 | AA32: 0.28449876 | AB32: 0.23732648 | AC32: -54.105813 | AD32: -32.191235 | AE32: -26.853659 | AF32: 0.73931878 | AG32: 0.56401639 | AH32: 0.64785666 | AI32: -0.31201861 | AJ32: -0.31201861 | AK32: -0.31201861 | AM32: -254.26147 | AN32: 32.825167 | AO32: 1.6409167 | AP32: 4.8025 | AQ32: 62.85825 | AR32: 72.8925 | AS32: 0.18755166 | AT32: 0.0093756309 | AU32: 0.027439826 | AV32: 0.35915032 | AW32: 0.41648256 | AX32: -47.68716 | AY32: -2.3838617 | AZ32: -6.9768903 | BA32: -91.318088 | BB32: -105.89547 | BC32: 1.075044 | BD32: 1.4091793 | BE32: 1.2348478 | BF32: 1.3220136 | BG32: 1.307486 | BH32: 0.45276217 | BI32: 0.45276217 | BJ32: 0.45276217 | BK32: 0.45276217 | BL32: 0.45276217 | BM32: 1.906051 | BN32: 1.906051 | BO32: 1.906051 | BP32: 1.906051 | BQ32: 1.906051 | BT32: -309.23904 | BU32: 0.27195 | BV32: 35 | BW32: 216.03771 | BX32: 67.770237 | BY32: 0.00085229437 | BZ32: 0.1096904 | CA32: 0.67706462 | CB32: 0.21239269 | CC32: 0.26356269 | CD32: 33.920552 | CE32: 209.37481 | CF32: 65.680111 | CG32: 0.71717739 | CH32: 0.38766346 | CI32: 1.7251024 | CJ32: 0.59118677 | CK32: -0.030841359 | CL32: -0.031822817 | CM32: -0.031822817 | CN32: -0.030841359 | CO32: 1.3014443 | CP32: 1.3014443 | CQ32: 1.3014443 | CR32: 1.3014443 | CU32: -69.972994 | CV32: 10.418583 | CW32: 2.0820132 | CX32: 5.7161717 | CY32: 9.5108002 | DB32: -107.83944 | DC32: 3.9429412 | DD32: 3.0648878 | DE32: 4.0648878 | DF32: 5.3332084 | DI32: -37.664361 | DJ32: 29 | DK32: 24.336667 | DL32: 0.54371602 | DM32: 0.45628398 | DN32: -20.478716 | DO32: -17.185645 | DP32: 0.61436149 | DQ32: 2.1043646 | DR32: 0.41610439 | DS32: 0.41610439 | DV32: -49.243382 | DW32: 1.648774 | DX32: 0.8074036 | DY32: 1.223508 | DZ32: 1.2371424
A33: 43831 | B33: -63.554037 | C33: 24.89 | D33: 4.98375 | E33: 28.169708 | F33: 0.42881663 | G33: 0.085862389 | H33: 0.48532098 | I33: -27.253028 | J33: -5.4569015 | K33: -30.844108 | L33: 1.0401919 | M33: 0.82120414 | N33: 0.93069802 | O33: 0.094938848 | P33: 0.094938848 | Q33: 0.094938848 | R33: 1.467001 | S33: 1.467001 | T33: 1.467001 | V33: -110.13787 | W33: 69.524167 | X33: 42.80625 | Y33: 35.2325 | Z33: 0.47114931 | AA33: 0.29008813 | AB33: 0.23876256 | AC33: -51.891384 | AD33: -31.94969 | AE33: -26.296801 | AF33: 0.70906013 | AG33: 0.55978431 | AH33: 0.63442222 | AI33: -0.33980174 | AJ33: -0.33980174 | AK33: -0.33980174 | AM33: -247.0438 | AN33: 33.26875 | AO33: 1.6070833 | AP33: 4.8025 | AQ33: 61.47675 | AR33: 74.512333 | AS33: 0.18938487 | AT33: 0.0091484429 | AU33: 0.027338593 | AV33: 0.34996103 | AW33: 0.42416707 | AX33: -46.786356 | AY33: -2.2600661 | AZ33: -6.7538298 | BA33: -86.455702 | BB33: -104.78784 | BC33: 1.0547366 | BD33: 1.3359997 | BE33: 1.1953681 | BF33: 1.2516207 | BG33: 1.2938102 | BH33: 0.40631543 | BI33: 0.40631543 | BJ33: 0.40631543 | BK33: 0.40631543 | BL33: 0.40631543 | BM33: 1.8841839 | BN33: 1.8841839 | BO33: 1.8841839 | BP33: 1.8841839 | BQ33: 1.8841839 | BT33: -306.49019 | BU33: 0.275625 | BV33: 34.125 | BW33: 222.10619 | BX33: 72.214187 | BY33: 0.00083847701 | BZ33: 0.10381144 | CA33: 0.67566778 | CB33: 0.21968231 | CC33: 0.25698498 | CD33: 31.817188 | CE33: 207.08555 | CF33: 67.330472 | CG33: 0.69927886 | CH33: 0.363625 | CI33: 1.7062404 | CJ33: 0.60604167 | CK33: -0.067628193 | CL33: -0.072533503 | CM33: -0.072533503 | CN33: -0.067628193 | CO33: 1.312248 | CP33: 1.312248 | CQ33: 1.312248 | CR33: 1.312248 | CU33: -67.639239 | CV33: 10.0825 | CW33: 2.0125735 | CX33: 5.7085782 | CY33: 9.6679869 | DB33: -107.80993 | DC33: 3.9418623 | DD33: 3.1493287 | DE33: 4.1493287 | DF33: 5.5592779 | DI33: -37.236777 | DJ33: 29 | DK33: 24.663333 | DL33: 0.54040624 | DM33: 0.45959376 | DN33: -20.122986 | DO33: -17.11379 | DP33: 0.60368959 | DQ33: 2.0955662 | DR33: 0.44113799 | DS33: 0.44113799 | DV33: -48.487357 | DW33: 1.6234606 | DX33: 0.86022375 | DY33: 1.3013617 | DZ33: 1.2338108
